Workbook

Sheet Recipe2
A1: Pozisyon | B1: Territory | C1: SiparişKodu | D1: BayiKodu | E1: BayiAdı | F1: ÜrünKodu | G1: ÜrünAdı | H1: Paket | I1: Karton | J1: ÖdemeTipi | K1: SiparişTarihi | L1: TeslimatTarihi | M1: BayiRutSırası
A2: D3JDR07 | B2: TERR030707-Sille | C2: D3J005897253121 | D2: D3J005897 | E2: NUR BAKKAL-BAHRİ DEMİR | F2: PLMNRCB | G2: PL Midnight Blue RCB | H2: 0 | I2: 2 | J2: VADE | K2: 06.11.2025 14:13:00 | L2: 07.11.2025 00:00:00 | M2: 24
A3: D3JDR07 | B3: TERR030707-Sille | C3: D3J005897253121 | D3: D3J005897 | E3: NUR BAKKAL-BAHRİ DEMİR | F3: MLFTB | G3: MLR Touch KS Box | H3: 0 | I3: 2 | J3: VADE | K3: 06.11.2025 14:13:00 | L3: 07.11.2025 00:00:00 | M3: 24
A4: D3JDR07 | B4: TERR030707-Sille | C4: D3J005897253121 | D4: D3J005897 | E4: NUR BAKKAL-BAHRİ DEMİR | F4: MLEDGE | G4: MLR Edge KS RCB | H4: 0 | I4: 8 | J4: VADE | K4: 06.11.2025 14:13:00 | L4: 07.11.2025 00:00:00 | M4: 24
A5: D3JDR07 | B5: TERR030707-Sille | C5: D3J005897253121 | D5: D3J005897 | E5: NUR BAKKAL-BAHRİ DEMİR | F5: MLTBLUE | G5: MLR Touch Blue | H5: 0 | I5: 15 | J5: VADE | K5: 06.11.2025 14:13:00 | L5: 07.11.2025 00:00:00 | M5: 24
A6: D3JDR07 | B6: TERR030707-Sille | C6: D3J005897253121 | D6: D3J005897 | E6: NUR BAKKAL-BAHRİ DEMİR | F6: CHNB100RCB | G6: CH NavyB 100 RCB | H6: 0 | I6: 1 | J6: VADE | K6: 06.11.2025 14:13:00 | L6: 07.11.2025 00:00:00 | M6: 24
A7: D3JDR07 | B7: TERR030707-Sille | C7: D3J005897253121 | D7: D3J005897 | E7: NUR BAKKAL-BAHRİ DEMİR | F7: PL100 | G7: PL Night 100 | H7: 0 | I7: 8 | J7: VADE | K7: 06.11.2025 14:13:00 | L7: 07.11.2025 00:00:00 | M7: 24
A8: D3JDR07 | B8: TERR030707-Sille | C8: D3J005897253121 | D8: D3J005897 | E8: NUR BAKKAL-BAHRİ DEMİR | F8: MFTB | G8: MLR KS Box | H8: 0 | I8: 2 | J8: VADE | K8: 06.11.2025 14:13:00 | L8: 07.11.2025 00:00:00 | M8: 24
A9: D3JDR07 | B9: TERR030707-Sille | C9: D3J005897253121 | D9: D3J005897 | E9: NUR BAKKAL-BAHRİ DEMİR | F9: CHNAVYBRCB | G9: CH NAVY BLUE RCB | H9: 0 | I9: 1 | J9: VADE | K9: 06.11.2025 14:13:00 | L9: 07.11.2025 00:00:00 | M9: 24
A10: D3JDR07 | B10: TERR030707-Sille | C10: D3J005897253121 | D10: D3J005897 | E10: NUR BAKKAL-BAHRİ DEMİR | F10: PLRC | G10: PL Night KS RCB | H10: 0 | I10: 20 | J10: VADE | K10: 06.11.2025 14:13:00 | L10: 07.11.2025 00:00:00 | M10: 24
A11: D3JDR07 | B11: TERR030707-Sille | C11: D3J005897253121 | D11: D3J005897 | E11: NUR BAKKAL-BAHRİ DEMİR | F11: MUARCB | G11: MUA Rosso KS RCB | H11: 5 | I11: 2 | J11: VADE | K11: 06.11.2025 14:13:00 | L11: 07.11.2025 00:00:00 | M11: 24
A12: D3JDR07 | B12: TERR030707-Sille | C12: D3J005897253121 | D12: D3J005897 | E12: NUR BAKKAL-BAHRİ DEMİR | F12: MLEDBLUE | G12: MLR Edge Blue KS RCB | H12: 0 | I12: 1 | J12: VADE | K12: 06.11.2025 14:13:00 | L12: 07.11.2025 00:00:00 | M12: 24
A13: D3JDR09 | B13: TERR030709-Şeker-Tekke | C13: 030038405253121 | D13: 030038405 | E13: KÖŞEM BAKKAL - HASAN YILMAZ | F13: MLR100 | G13: MLR 100 | H13: 0 | I13: 1 | J13: HAVALE | K13: 06.11.2025 14:13:00 | L13: 07.11.2025 00:00:00 | M13: 23
... A533: D3JDR04 | B533: TERR030704-Mevlana | C533: D3J005692253121 | D533: D3J005692 | E533: ENLİ MARKET RÜSTEM ENLİ | F533: LM100RCB | G533: L&M Red 100 RCB | H533: 5 | I533: 0 | J533: VADE | K533: 06.11.2025 16:54:00 | L533: 07.11.2025 00:00:00 | M533: 43

Sheet Hazırlık
E2: İstasyon1 | N2: İstasyon1
F3: 5 | N3: Sayım
B4: bugün depoda kaç kişi var | F4: =SUM(G32:K32) -> 833 | AC4: Satır Etiketleri | AD4: Toplam Paket | AE4: Toplam Karton
G5: TERR030716-Lalebahçe | H5: TERR030704-Mevlana | I5: TERR030709-Şeker-Tekke | J5: TERR030703-Sanayi | K5: TERR030724-Yazır | L5: Toplam Çekilecek Stok | P5: Sayım1 | Q5: Sayım2 | R5: Sayım3 | S5: Sayım4 | AC5: TERR030701-Bosna-Hersek | AD5: 83 | AE5: 146 | AF5: =AD5/10+AE5 -> 154.3
F6: MLR100 | G6: =SUMIFS(Recipe2!$H:$H,Recipe2!$B:$B,Hazırlık!G$5,Recipe2!$F:$F,Hazırlık!$F6)/10+SUMIFS(Recipe2!$I:$I,Recipe2!$B:$B,Hazırlık!G$5,Recipe2!$F:$F,Hazırlık!$F6) -> 0 | H6: =SUMIFS(Recipe2!$H:$H,Recipe2!$B:$B,Hazırlık!H$5,Recipe2!$F:$F,Hazırlık!$F6)/10+SUMIFS(Recipe2!$I:$I,Recipe2!$B:$B,Hazırlık!H$5,Recipe2!$F:$F,Hazırlık!$F6) -> 0.5 | I6: =SUMIFS(Recipe2!$H:$H,Recipe2!$B:$B,Hazırlık!I$5,Recipe2!$F:$F,Hazırlık!$F6)/10+SUMIFS(Recipe2!$I:$I,Recipe2!$B:$B,Hazırlık!I$5,Recipe2!$F:$F,Hazırlık!$F6) -> 5 | J6: =SUMIFS(Recipe2!$H:$H,Recipe2!$B:$B,Hazırlık!J$5,Recipe2!$F:$F,Hazırlık!$F6)/10+SUMIFS(Recipe2!$I:$I,Recipe2!$B:$B,Hazırlık!J$5,Recipe2!$F:$F,Hazırlık!$F6) -> 5 | K6: =SUMIFS(Recipe2!$H:$H,Recipe2!$B:$B,Hazırlık!K$5,Recipe2!$F:$F,Hazırlık!$F6)/10+SUMIFS(Recipe2!$I:$I,Recipe2!$B:$B,Hazırlık!K$5,Recipe2!$F:$F,Hazırlık!$F6) -> 3.5 | L6: =SUM(G6:K6) -> 14 | O6: MLR100 | P6: =SUM(H6:K6) -> 14 | Q6: =SUM(I6:K6) -> 13.5 | R6: =SUM(J6:K6) -> 8.5 | S6: =SUM(K6) -> 3.5 | AC6: TERR030702-Kadınlarpazarı | AD6: 23 | AE6: 24 | AF6: =AD6/10+AE6 -> 26.3
F7: MFTB | G7: =SUMIFS(Recipe2!$H:$H,Recipe2!$B:$B,Hazırlık!G$5,Recipe2!$F:$F,Hazırlık!$F7)/10+SUMIFS(Recipe2!$I:$I,Recipe2!$B:$B,Hazırlık!G$5,Recipe2!$F:$F,Hazırlık!$F7) -> 0 | H7: =SUMIFS(Recipe2!$H:$H,Recipe2!$B:$B,Hazırlık!H$5,Recipe2!$F:$F,Hazırlık!$F7)/10+SUMIFS(Recipe2!$I:$I,Recipe2!$B:$B,Hazırlık!H$5,Recipe2!$F:$F,Hazırlık!$F7) -> 0 | I7: =SUMIFS(Recipe2!$H:$H,Recipe2!$B:$B,Hazırlık!I$5,Recipe2!$F:$F,Hazırlık!$F7)/10+SUMIFS(Recipe2!$I:$I,Recipe2!$B:$B,Hazırlık!I$5,Recipe2!$F:$F,Hazırlık!$F7) -> 2.5 | J7: =SUMIFS(Recipe2!$H:$H,Recipe2!$B:$B,Hazırlık!J$5,Recipe2!$F:$F,Hazırlık!$F7)/10+SUMIFS(Recipe2!$I:$I,Recipe2!$B:$B,Hazırlık!J$5,Recipe2!$F:$F,Hazırlık!$F7) -> 7 | K7: =SUMIFS(Recipe2!$H:$H,Recipe2!$B:$B,Hazırlık!K$5,Recipe2!$F:$F,Hazırlık!$F7)/10+SUMIFS(Recipe2!$I:$I,Recipe2!$B:$B,Hazırlık!K$5,Recipe2!$F:$F,Hazırlık!$F7) -> 4 | L7: =SUM(G7:K7) -> 13.5 | O7: MFTB | P7: =SUM(H7:K7) -> 13.5 | Q7: =SUM(I7:K7) -> 13.5 | R7: =SUM(J7:K7) -> 11 | S7: =SUM(K7) -> 4 | AC7: TERR030703-Sanayi | AD7: 16 | AE7: 590 | AF7: =AD7/10+AE7 -> 591.6
F8: MLFTB | G8: =SUMIFS(Recipe2!$H:$H,Recipe2!$B:$B,Hazırlık!G$5,Recipe2!$F:$F,Hazırlık!$F8)/10+SUMIFS(Recipe2!$I:$I,Recipe2!$B:$B,Hazırlık!G$5,Recipe2!$F:$F,Hazırlık!$F8) -> 0 | H8: =SUMIFS(Recipe2!$H:$H,Recipe2!$B:$B,Hazırlık!H$5,Recipe2!$F:$F,Hazırlık!$F8)/10+SUMIFS(Recipe2!$I:$I,Recipe2!$B:$B,Hazırlık!H$5,Recipe2!$F:$F,Hazırlık!$F8) -> 1.5 | I8: =SUMIFS(Recipe2!$H:$H,Recipe2!$B:$B,Hazırlık!I$5,Recipe2!$F:$F,Hazırlık!$F8)/10+SUMIFS(Recipe2!$I:$I,Recipe2!$B:$B,Hazırlık!I$5,Recipe2!$F:$F,Hazırlık!$F8) -> 5.5 | J8: =SUMIFS(Recipe2!$H:$H,Recipe2!$B:$B,Hazırlık!J$5,Recipe2!$F:$F,Hazırlık!$F8)/10+SUMIFS(Recipe2!$I:$I,Recipe2!$B:$B,Hazırlık!J$5,Recipe2!$F:$F,Hazırlık!$F8) -> 8.5 | K8: =SUMIFS(Recipe2!$H:$H,Recipe2!$B:$B,Hazırlık!K$5,Recipe2!$F:$F,Hazırlık!$F8)/10+SUMIFS(Recipe2!$I:$I,Recipe2!$B:$B,Hazırlık!K$5,Recipe2!$F:$F,Hazırlık!$F8) -> 1 | L8: =SUM(G8:K8) -> 16.5 | O8: MLFTB | P8: =SUM(H8:K8) -> 16.5 | Q8: =SUM(I8:K8) -> 15 | R8: =SUM(J8:K8) -> 9.5 | S8: =SUM(K8) -> 1 | AC8: TERR030704-Mevlana | AD8: 131 | AE8: 88 | AF8: =AD8/10+AE8 -> 101.1
F9: MLTBLUE | G9: =SUMIFS(Recipe2!$H:$H,Recipe2!$B:$B,Hazırlık!G$5,Recipe2!$F:$F,Hazırlık!$F9)/10+SUMIFS(Recipe2!$I:$I,Recipe2!$B:$B,Hazırlık!G$5,Recipe2!$F:$F,Hazırlık!$F9) -> 2 | H9: =SUMIFS(Recipe2!$H:$H,Recipe2!$B:$B,Hazırlık!H$5,Recipe2!$F:$F,Hazırlık!$F9)/10+SUMIFS(Recipe2!$I:$I,Recipe2!$B:$B,Hazırlık!H$5,Recipe2!$F:$F,Hazırlık!$F9) -> 8 | I9: =SUMIFS(Recipe2!$H:$H,Recipe2!$B:$B,Hazırlık!I$5,Recipe2!$F:$F,Hazırlık!$F9)/10+SUMIFS(Recipe2!$I:$I,Recipe2!$B:$B,Hazırlık!I$5,Recipe2!$F:$F,Hazırlık!$F9) -> 19 | J9: =SUMIFS(Recipe2!$H:$H,Recipe2!$B:$B,Hazırlık!J$5,Recipe2!$F:$F,Hazırlık!$F9)/10+SUMIFS(Recipe2!$I:$I,Recipe2!$B:$B,Hazırlık!J$5,Recipe2!$F:$F,Hazırlık!$F9) -> 100 | K9: =SUMIFS(Recipe2!$H:$H,Recipe2!$B:$B,Hazırlık!K$5,Recipe2!$F:$F,Hazırlık!$F9)/10+SUMIFS(Recipe2!$I:$I,Recipe2!$B:$B,Hazırlık!K$5,Recipe2!$F:$F,Hazırlık!$F9) -> 26 | L9: =SUM(G9:K9) -> 155 | O9: MLTBLUE | P9: =SUM(H9:K9) -> 153 | Q9: =SUM(I9:K9) -> 145 | R9: =SUM(J9:K9) -> 126 | S9: =SUM(K9) -> 26 | AC9: TERR030705-Meram | AD9: 59 | AE9: 138 | AF9: =AD9/10+AE9 -> 143.9
F10: MLTGRAY | G10: =SUMIFS(Recipe2!$H:$H,Recipe2!$B:$B,Hazırlık!G$5,Recipe2!$F:$F,Hazırlık!$F10)/10+SUMIFS(Recipe2!$I:$I,Recipe2!$B:$B,Hazırlık!G$5,Recipe2!$F:$F,Hazırlık!$F10) -> 0 | H10: =SUMIFS(Recipe2!$H:$H,Recipe2!$B:$B,Hazırlık!H$5,Recipe2!$F:$F,Hazırlık!$F10)/10+SUMIFS(Recipe2!$I:$I,Recipe2!$B:$B,Hazırlık!H$5,Recipe2!$F:$F,Hazırlık!$F10) -> 0 | I10: =SUMIFS(Recipe2!$H:$H,Recipe2!$B:$B,Hazırlık!I$5,Recipe2!$F:$F,Hazırlık!$F10)/10+SUMIFS(Recipe2!$I:$I,Recipe2!$B:$B,Hazırlık!I$5,Recipe2!$F:$F,Hazırlık!$F10) -> 2.4 | J10: =SUMIFS(Recipe2!$H:$H,Recipe2!$B:$B,Hazırlık!J$5,Recipe2!$F:$F,Hazırlık!$F10)/10+SUMIFS(Recipe2!$I:$I,Recipe2!$B:$B,Hazırlık!J$5,Recipe2!$F:$F,Hazırlık!$F10) -> 0 | K10: =SUMIFS(Recipe2!$H:$H,Recipe2!$B:$B,Hazırlık!K$5,Recipe2!$F:$F,Hazırlık!$F10)/10+SUMIFS(Recipe2!$I:$I,Recipe2!$B:$B,Hazırlık!K$5,Recipe2!$F:$F,Hazırlık!$F10) -> 0 | L10: =SUM(G10:K10) -> 2.4 | O10: MLTGRAY | P10: =SUM(H10:K10) -> 2.4 | Q10: =SUM(I10:K10) -> 2.4 | R10: =SUM(J10:K10) -> 0 | S10: =SUM(K10) -> 0 | AC10: TERR030707-Sille | AD10: 128 | AE10: 236 | AF10: =AD10/10+AE10 -> 248.8
F11: MLTONE | G11: =SUMIFS(Recipe2!$H:$H,Recipe2!$B:$B,Hazırlık!G$5,Recipe2!$F:$F,Hazırlık!$F11)/10+SUMIFS(Recipe2!$I:$I,Recipe2!$B:$B,Hazırlık!G$5,Recipe2!$F:$F,Hazırlık!$F11) -> 0 | H11: =SUMIFS(Recipe2!$H:$H,Recipe2!$B:$B,Hazırlık!H$5,Recipe2!$F:$F,Hazırlık!$F11)/10+SUMIFS(Recipe2!$I:$I,Recipe2!$B:$B,Hazırlık!H$5,Recipe2!$F:$F,Hazırlık!$F11) -> 0 | I11: =SUMIFS(Recipe2!$H:$H,Recipe2!$B:$B,Hazırlık!I$5,Recipe2!$F:$F,Hazırlık!$F11)/10+SUMIFS(Recipe2!$I:$I,Recipe2!$B:$B,Hazırlık!I$5,Recipe2!$F:$F,Hazırlık!$F11) -> 1 | J11: =SUMIFS(Recipe2!$H:$H,Recipe2!$B:$B,Hazırlık!J$5,Recipe2!$F:$F,Hazırlık!$F11)/10+SUMIFS(Recipe2!$I:$I,Recipe2!$B:$B,Hazırlık!J$5,Recipe2!$F:$F,Hazırlık!$F11) -> 5 | K11: =SUMIFS(Recipe2!$H:$H,Recipe2!$B:$B,Hazırlık!K$5,Recipe2!$F:$F,Hazırlık!$F11)/10+SUMIFS(Recipe2!$I:$I,Recipe2!$B:$B,Hazırlık!K$5,Recipe2!$F:$F,Hazırlık!$F11) -> 0 | L11: =SUM(G11:K11) -> 6 | O11: MLTONE | P11: =SUM(H11:K11) -> 6 | Q11: =SUM(I11:K11) -> 6 | R11: =SUM(J11:K11) -> 5 | S11: =SUM(K11) -> 0 | AC11: TERR030708-Form | AD11: 29 | AE11: 79 | AF11: =AD11/10+AE11 -> 81.9
F12: MLEDGE | G12: =SUMIFS(Recipe2!$H:$H,Recipe2!$B:$B,Hazırlık!G$5,Recipe2!$F:$F,Hazırlık!$F12)/10+SUMIFS(Recipe2!$I:$I,Recipe2!$B:$B,Hazırlık!G$5,Recipe2!$F:$F,Hazırlık!$F12) -> 0 | H12: =SUMIFS(Recipe2!$H:$H,Recipe2!$B:$B,Hazırlık!H$5,Recipe2!$F:$F,Hazırlık!$F12)/10+SUMIFS(Recipe2!$I:$I,Recipe2!$B:$B,Hazırlık!H$5,Recipe2!$F:$F,Hazırlık!$F12) -> 13 | I12: =SUMIFS(Recipe2!$H:$H,Recipe2!$B:$B,Hazırlık!I$5,Recipe2!$F:$F,Hazırlık!$F12)/10+SUMIFS(Recipe2!$I:$I,Recipe2!$B:$B,Hazırlık!I$5,Recipe2!$F:$F,Hazırlık!$F12) -> 7 | J12: =SUMIFS(Recipe2!$H:$H,Recipe2!$B:$B,Hazırlık!J$5,Recipe2!$F:$F,Hazırlık!$F12)/10+SUMIFS(Recipe2!$I:$I,Recipe2!$B:$B,Hazırlık!J$5,Recipe2!$F:$F,Hazırlık!$F12) -> 75 | K12: =SUMIFS(Recipe2!$H:$H,Recipe2!$B:$B,Hazırlık!K$5,Recipe2!$F:$F,Hazırlık!$F12)/10+SUMIFS(Recipe2!$I:$I,Recipe2!$B:$B,Hazırlık!K$5,Recipe2!$F:$F,Hazırlık!$F12) -> 22 | L12: =SUM(G12:K12) -> 117 | O12: MLEDGE | P12: =SUM(H12:K12) -> 117 | Q12: =SUM(I12:K12) -> 104 | R12: =SUM(J12:K12) -> 97 | S12: =SUM(K12) -> 22 | AC12: TERR030709-Şeker-Tekke | AD12: 78 | AE12: 79 | AF12: =AD12/10+AE12 -> 86.8
F13: MLEDBLUE | G13: =SUMIFS(Recipe2!$H:$H,Recipe2!$B:$B,Hazırlık!G$5,Recipe2!$F:$F,Hazırlık!$F13)/10+SUMIFS(Recipe2!$I:$I,Recipe2!$B:$B,Hazırlık!G$5,Recipe2!$F:$F,Hazırlık!$F13) -> 0 | H13: =SUMIFS(Recipe2!$H:$H,Recipe2!$B:$B,Hazırlık!H$5,Recipe2!$F:$F,Hazırlık!$F13)/10+SUMIFS(Recipe2!$I:$I,Recipe2!$B:$B,Hazırlık!H$5,Recipe2!$F:$F,Hazırlık!$F13) -> 2.5 | I13: =SUMIFS(Recipe2!$H:$H,Recipe2!$B:$B,Hazırlık!I$5,Recipe2!$F:$F,Hazırlık!$F13)/10+SUMIFS(Recipe2!$I:$I,Recipe2!$B:$B,Hazırlık!I$5,Recipe2!$F:$F,Hazırlık!$F13) -> 1 | J13: =SUMIFS(Recipe2!$H:$H,Recipe2!$B:$B,Hazırlık!J$5,Recipe2!$F:$F,Hazırlık!$F13)/10+SUMIFS(Recipe2!$I:$I,Recipe2!$B:$B,Hazırlık!J$5,Recipe2!$F:$F,Hazırlık!$F13) -> 40 | K13: =SUMIFS(Recipe2!$H:$H,Recipe2!$B:$B,Hazırlık!K$5,Recipe2!$F:$F,Hazırlık!$F13)/10+SUMIFS(Recipe2!$I:$I,Recipe2!$B:$B,Hazırlık!K$5,Recipe2!$F:$F,Hazırlık!$F13) -> 8 | L13: =SUM(G13:K13) -> 51.5 | O13: MLEDBLUE | P13: =SUM(H13:K13) -> 51.5 | Q13: =SUM(I13:K13) -> 49 | R13: =SUM(J13:K13) -> 48 | S13: =SUM(K13) -> 8 | AC13: TERR030713-Büsan | AD13: 172 | AE13: 269 | AF13: =AD13/10+AE13 -> 286.2
F14: PL100 | G14: =SUMIFS(Recipe2!$H:$H,Recipe2!$B:$B,Hazırlık!G$5,Recipe2!$F:$F,Hazırlık!$F14)/10+SUMIFS(Recipe2!$I:$I,Recipe2!$B:$B,Hazırlık!G$5,Recipe2!$F:$F,Hazırlık!$F14) -> 0 | H14: =SUMIFS(Recipe2!$H:$H,Recipe2!$B:$B,Hazırlık!H$5,Recipe2!$F:$F,Hazırlık!$F14)/10+SUMIFS(Recipe2!$I:$I,Recipe2!$B:$B,Hazırlık!H$5,Recipe2!$F:$F,Hazırlık!$F14) -> 6 | I14: =SUMIFS(Recipe2!$H:$H,Recipe2!$B:$B,Hazırlık!I$5,Recipe2!$F:$F,Hazırlık!$F14)/10+SUMIFS(Recipe2!$I:$I,Recipe2!$B:$B,Hazırlık!I$5,Recipe2!$F:$F,Hazırlık!$F14) -> 11 | J14: =SUMIFS(Recipe2!$H:$H,Recipe2!$B:$B,Hazırlık!J$5,Recipe2!$F:$F,Hazırlık!$F14)/10+SUMIFS(Recipe2!$I:$I,Recipe2!$B:$B,Hazırlık!J$5,Recipe2!$F:$F,Hazırlık!$F14) -> 70 | K14: =SUMIFS(Recipe2!$H:$H,Recipe2!$B:$B,Hazırlık!K$5,Recipe2!$F:$F,Hazırlık!$F14)/10+SUMIFS(Recipe2!$I:$I,Recipe2!$B:$B,Hazırlık!K$5,Recipe2!$F:$F,Hazırlık!$F14) -> 20 | L14: =SUM(G14:K14) -> 107 | O14: PL100 | P14: =SUM(H14:K14) -> 107 | Q14: =SUM(I14:K14) -> 101 | R14: =SUM(J14:K14) -> 90 | S14: =SUM(K14) -> 20 | AC14: TERR030714-Adliye | AD14: 14 | AE14: 188 | AF14: =AD14/10+AE14 -> 189.4
F15: PLLONGRCB | G15: =SUMIFS(Recipe2!$H:$H,Recipe2!$B:$B,Hazırlık!G$5,Recipe2!$F:$F,Hazırlık!$F15)/10+SUMIFS(Recipe2!$I:$I,Recipe2!$B:$B,Hazırlık!G$5,Recipe2!$F:$F,Hazırlık!$F15) -> 0 | H15: =SUMIFS(Recipe2!$H:$H,Recipe2!$B:$B,Hazırlık!H$5,Recipe2!$F:$F,Hazırlık!$F15)/10+SUMIFS(Recipe2!$I:$I,Recipe2!$B:$B,Hazırlık!H$5,Recipe2!$F:$F,Hazırlık!$F15) -> 0 | I15: =SUMIFS(Recipe2!$H:$H,Recipe2!$B:$B,Hazırlık!I$5,Recipe2!$F:$F,Hazırlık!$F15)/10+SUMIFS(Recipe2!$I:$I,Recipe2!$B:$B,Hazırlık!I$5,Recipe2!$F:$F,Hazırlık!$F15) -> 1.4 | J15: =SUMIFS(Recipe2!$H:$H,Recipe2!$B:$B,Hazırlık!J$5,Recipe2!$F:$F,Hazırlık!$F15)/10+SUMIFS(Recipe2!$I:$I,Recipe2!$B:$B,Hazırlık!J$5,Recipe2!$F:$F,Hazırlık!$F15) -> 5.6 | K15: =SUMIFS(Recipe2!$H:$H,Recipe2!$B:$B,Hazırlık!K$5,Recipe2!$F:$F,Hazırlık!$F15)/10+SUMIFS(Recipe2!$I:$I,Recipe2!$B:$B,Hazırlık!K$5,Recipe2!$F:$F,Hazırlık!$F15) -> 1 | L15: =SUM(G15:K15) -> 8 | O15: PLLONGRCB | P15: =SUM(H15:K15) -> 8 | Q15: =SUM(I15:K15) -> 8 | R15: =SUM(J15:K15) -> 6.6 | S15: =SUM(K15) -> 1 | AC15: TERR030716-Lalebahçe | AD15: 16 | AE15: 15 | AF15: =AD15/10+AE15 -> 16.6
F16: PLRC | G16: =SUMIFS(Recipe2!$H:$H,Recipe2!$B:$B,Hazırlık!G$5,Recipe2!$F:$F,Hazırlık!$F16)/10+SUMIFS(Recipe2!$I:$I,Recipe2!$B:$B,Hazırlık!G$5,Recipe2!$F:$F,Hazırlık!$F16) -> 2 | H16: =SUMIFS(Recipe2!$H:$H,Recipe2!$B:$B,Hazırlık!H$5,Recipe2!$F:$F,Hazırlık!$F16)/10+SUMIFS(Recipe2!$I:$I,Recipe2!$B:$B,Hazırlık!H$5,Recipe2!$F:$F,Hazırlık!$F16) -> 13 | I16: =SUMIFS(Recipe2!$H:$H,Recipe2!$B:$B,Hazırlık!I$5,Recipe2!$F:$F,Hazırlık!$F16)/10+SUMIFS(Recipe2!$I:$I,Recipe2!$B:$B,Hazırlık!I$5,Recipe2!$F:$F,Hazırlık!$F16) -> 11 | J16: =SUMIFS(Recipe2!$H:$H,Recipe2!$B:$B,Hazırlık!J$5,Recipe2!$F:$F,Hazırlık!$F16)/10+SUMIFS(Recipe2!$I:$I,Recipe2!$B:$B,Hazırlık!J$5,Recipe2!$F:$F,Hazırlık!$F16) -> 115 | K16: =SUMIFS(Recipe2!$H:$H,Recipe2!$B:$B,Hazırlık!K$5,Recipe2!$F:$F,Hazırlık!$F16)/10+SUMIFS(Recipe2!$I:$I,Recipe2!$B:$B,Hazırlık!K$5,Recipe2!$F:$F,Hazırlık!$F16) -> 43 | L16: =SUM(G16:K16) -> 184 | O16: PLRC | P16: =SUM(H16:K16) -> 182 | Q16: =SUM(I16:K16) -> 169 | R16: =SUM(J16:K16) -> 158 | S16: =SUM(K16) -> 43 | AC16: TERR030723-Çevreyolu | AD16: 70 | AE16: 51 | AF16: =AD16/10+AE16 -> 58
F17: PLLRC | G17: =SUMIFS(Recipe2!$H:$H,Recipe2!$B:$B,Hazırlık!G$5,Recipe2!$F:$F,Hazırlık!$F17)/10+SUMIFS(Recipe2!$I:$I,Recipe2!$B:$B,Hazırlık!G$5,Recipe2!$F:$F,Hazırlık!$F17) -> 0 | H17: =SUMIFS(Recipe2!$H:$H,Recipe2!$B:$B,Hazırlık!H$5,Recipe2!$F:$F,Hazırlık!$F17)/10+SUMIFS(Recipe2!$I:$I,Recipe2!$B:$B,Hazırlık!H$5,Recipe2!$F:$F,Hazırlık!$F17) -> 0 | I17: =SUMIFS(Recipe2!$H:$H,Recipe2!$B:$B,Hazırlık!I$5,Recipe2!$F:$F,Hazırlık!$F17)/10+SUMIFS(Recipe2!$I:$I,Recipe2!$B:$B,Hazırlık!I$5,Recipe2!$F:$F,Hazırlık!$F17) -> 0 | J17: =SUMIFS(Recipe2!$H:$H,Recipe2!$B:$B,Hazırlık!J$5,Recipe2!$F:$F,Hazırlık!$F17)/10+SUMIFS(Recipe2!$I:$I,Recipe2!$B:$B,Hazırlık!J$5,Recipe2!$F:$F,Hazırlık!$F17) -> 7 | K17: =SUMIFS(Recipe2!$H:$H,Recipe2!$B:$B,Hazırlık!K$5,Recipe2!$F:$F,Hazırlık!$F17)/10+SUMIFS(Recipe2!$I:$I,Recipe2!$B:$B,Hazırlık!K$5,Recipe2!$F:$F,Hazırlık!$F17) -> 1 | L17: =SUM(G17:K17) -> 8 | O17: PLLRC | P17: =SUM(H17:K17) -> 8 | Q17: =SUM(I17:K17) -> 8 | R17: =SUM(J17:K17) -> 8 | S17: =SUM(K17) -> 1 | AC17: TERR030724-Yazır | AD17: 14 | AE17: 153 | AF17: =AD17/10+AE17 -> 154.4
... F19: PLRSVRCB | G19: =SUMIFS(Recipe2!$H:$H,Recipe2!$B:$B,Hazırlık!G$5,Recipe2!$F:$F,Hazırlık!$F19)/10+SUMIFS(Recipe2!$I:$I,Recipe2!$B:$B,Hazırlık!G$5,Recipe2!$F:$F,Hazırlık!$F19) -> 0 | H19: =SUMIFS(Recipe2!$H:$H,Recipe2!$B:$B,Hazırlık!H$5,Recipe2!$F:$F,Hazırlık!$F19)/10+SUMIFS(Recipe2!$I:$I,Recipe2!$B:$B,Hazırlık!H$5,Recipe2!$F:$F,Hazırlık!$F19) -> 0 | I19: =SUMIFS(Recipe2!$H:$H,Recipe2!$B:$B,Hazırlık!I$5,Recipe2!$F:$F,Hazırlık!$F19)/10+SUMIFS(Recipe2!$I:$I,Recipe2!$B:$B,Hazırlık!I$5,Recipe2!$F:$F,Hazırlık!$F19) -> 2 | J19: =SUMIFS(Recipe2!$H:$H,Recipe2!$B:$B,Hazırlık!J$5,Recipe2!$F:$F,Hazırlık!$F19)/10+SUMIFS(Recipe2!$I:$I,Recipe2!$B:$B,Hazırlık!J$5,Recipe2!$F:$F,Hazırlık!$F19) -> 5 | K19: =SUMIFS(Recipe2!$H:$H,Recipe2!$B:$B,Hazırlık!K$5,Recipe2!$F:$F,Hazırlık!$F19)/10+SUMIFS(Recipe2!$I:$I,Recipe2!$B:$B,Hazırlık!K$5,Recipe2!$F:$F,Hazırlık!$F19) -> 1 | L19: =SUM(G19:K19) -> 8 | O19: PLRSVRCB | P19: =SUM(H19:K19) -> 8 | Q19: =SUM(I19:K19) -> 8 | R19: =SUM(J19:K19) -> 6 | S19: =SUM(K19) -> 1 | AC19: Genel Toplam | AD19: 848 | AE19: 2132 | AF19: =AD19/10+AE19 -> 2216.8
F20: PLMNRCB | G20: =SUMIFS(Recipe2!$H:$H,Recipe2!$B:$B,Hazırlık!G$5,Recipe2!$F:$F,Hazırlık!$F20)/10+SUMIFS(Recipe2!$I:$I,Recipe2!$B:$B,Hazırlık!G$5,Recipe2!$F:$F,Hazırlık!$F20) -> 0 | H20: =SUMIFS(Recipe2!$H:$H,Recipe2!$B:$B,Hazırlık!H$5,Recipe2!$F:$F,Hazırlık!$F20)/10+SUMIFS(Recipe2!$I:$I,Recipe2!$B:$B,Hazırlık!H$5,Recipe2!$F:$F,Hazırlık!$F20) -> 4 | I20: =SUMIFS(Recipe2!$H:$H,Recipe2!$B:$B,Hazırlık!I$5,Recipe2!$F:$F,Hazırlık!$F20)/10+SUMIFS(Recipe2!$I:$I,Recipe2!$B:$B,Hazırlık!I$5,Recipe2!$F:$F,Hazırlık!$F20) -> 4 | J20: =SUMIFS(Recipe2!$H:$H,Recipe2!$B:$B,Hazırlık!J$5,Recipe2!$F:$F,Hazırlık!$F20)/10+SUMIFS(Recipe2!$I:$I,Recipe2!$B:$B,Hazırlık!J$5,Recipe2!$F:$F,Hazırlık!$F20) -> 15 | K20: =SUMIFS(Recipe2!$H:$H,Recipe2!$B:$B,Hazırlık!K$5,Recipe2!$F:$F,Hazırlık!$F20)/10+SUMIFS(Recipe2!$I:$I,Recipe2!$B:$B,Hazırlık!K$5,Recipe2!$F:$F,Hazırlık!$F20) -> 9 | L20: =SUM(G20:K20) -> 32 | O20: PLMNRCB | P20: =SUM(H20:K20) -> 32 | Q20: =SUM(I20:K20) -> 28 | R20: =SUM(J20:K20) -> 24 | S20: =SUM(K20) -> 9
F21: LAB100RCB | G21: =SUMIFS(Recipe2!$H:$H,Recipe2!$B:$B,Hazırlık!G$5,Recipe2!$F:$F,Hazırlık!$F21)/10+SUMIFS(Recipe2!$I:$I,Recipe2!$B:$B,Hazırlık!G$5,Recipe2!$F:$F,Hazırlık!$F21) -> 0 | H21: =SUMIFS(Recipe2!$H:$H,Recipe2!$B:$B,Hazırlık!H$5,Recipe2!$F:$F,Hazırlık!$F21)/10+SUMIFS(Recipe2!$I:$I,Recipe2!$B:$B,Hazırlık!H$5,Recipe2!$F:$F,Hazırlık!$F21) -> 5.5 | I21: =SUMIFS(Recipe2!$H:$H,Recipe2!$B:$B,Hazırlık!I$5,Recipe2!$F:$F,Hazırlık!$F21)/10+SUMIFS(Recipe2!$I:$I,Recipe2!$B:$B,Hazırlık!I$5,Recipe2!$F:$F,Hazırlık!$F21) -> 0.5 | J21: =SUMIFS(Recipe2!$H:$H,Recipe2!$B:$B,Hazırlık!J$5,Recipe2!$F:$F,Hazırlık!$F21)/10+SUMIFS(Recipe2!$I:$I,Recipe2!$B:$B,Hazırlık!J$5,Recipe2!$F:$F,Hazırlık!$F21) -> 5 | K21: =SUMIFS(Recipe2!$H:$H,Recipe2!$B:$B,Hazırlık!K$5,Recipe2!$F:$F,Hazırlık!$F21)/10+SUMIFS(Recipe2!$I:$I,Recipe2!$B:$B,Hazırlık!K$5,Recipe2!$F:$F,Hazırlık!$F21) -> 1 | L21: =SUM(G21:K21) -> 12 | O21: LAB100RCB | P21: =SUM(H21:K21) -> 12 | Q21: =SUM(I21:K21) -> 6.5 | R21: =SUM(J21:K21) -> 6 | S21: =SUM(K21) -> 1
F22: LARKBRCB | G22: =SUMIFS(Recipe2!$H:$H,Recipe2!$B:$B,Hazırlık!G$5,Recipe2!$F:$F,Hazırlık!$F22)/10+SUMIFS(Recipe2!$I:$I,Recipe2!$B:$B,Hazırlık!G$5,Recipe2!$F:$F,Hazırlık!$F22) -> 0 | H22: =SUMIFS(Recipe2!$H:$H,Recipe2!$B:$B,Hazırlık!H$5,Recipe2!$F:$F,Hazırlık!$F22)/10+SUMIFS(Recipe2!$I:$I,Recipe2!$B:$B,Hazırlık!H$5,Recipe2!$F:$F,Hazırlık!$F22) -> 5.5 | I22: =SUMIFS(Recipe2!$H:$H,Recipe2!$B:$B,Hazırlık!I$5,Recipe2!$F:$F,Hazırlık!$F22)/10+SUMIFS(Recipe2!$I:$I,Recipe2!$B:$B,Hazırlık!I$5,Recipe2!$F:$F,Hazırlık!$F22) -> 0.5 | J22: =SUMIFS(Recipe2!$H:$H,Recipe2!$B:$B,Hazırlık!J$5,Recipe2!$F:$F,Hazırlık!$F22)/10+SUMIFS(Recipe2!$I:$I,Recipe2!$B:$B,Hazırlık!J$5,Recipe2!$F:$F,Hazırlık!$F22) -> 0 | K22: =SUMIFS(Recipe2!$H:$H,Recipe2!$B:$B,Hazırlık!K$5,Recipe2!$F:$F,Hazırlık!$F22)/10+SUMIFS(Recipe2!$I:$I,Recipe2!$B:$B,Hazırlık!K$5,Recipe2!$F:$F,Hazırlık!$F22) -> 3 | L22: =SUM(G22:K22) -> 9 | O22: LARKBRCB | P22: =SUM(H22:K22) -> 9 | Q22: =SUM(I22:K22) -> 3.5 | R22: =SUM(J22:K22) -> 3 | S22: =SUM(K22) -> 3
F23: CHNB100RCB | G23: =SUMIFS(Recipe2!$H:$H,Recipe2!$B:$B,Hazırlık!G$5,Recipe2!$F:$F,Hazırlık!$F23)/10+SUMIFS(Recipe2!$I:$I,Recipe2!$B:$B,Hazırlık!G$5,Recipe2!$F:$F,Hazırlık!$F23) -> 0 | H23: =SUMIFS(Recipe2!$H:$H,Recipe2!$B:$B,Hazırlık!H$5,Recipe2!$F:$F,Hazırlık!$F23)/10+SUMIFS(Recipe2!$I:$I,Recipe2!$B:$B,Hazırlık!H$5,Recipe2!$F:$F,Hazırlık!$F23) -> 1.5 | I23: =SUMIFS(Recipe2!$H:$H,Recipe2!$B:$B,Hazırlık!I$5,Recipe2!$F:$F,Hazırlık!$F23)/10+SUMIFS(Recipe2!$I:$I,Recipe2!$B:$B,Hazırlık!I$5,Recipe2!$F:$F,Hazırlık!$F23) -> 1 | J23: =SUMIFS(Recipe2!$H:$H,Recipe2!$B:$B,Hazırlık!J$5,Recipe2!$F:$F,Hazırlık!$F23)/10+SUMIFS(Recipe2!$I:$I,Recipe2!$B:$B,Hazırlık!J$5,Recipe2!$F:$F,Hazırlık!$F23) -> 5 | K23: =SUMIFS(Recipe2!$H:$H,Recipe2!$B:$B,Hazırlık!K$5,Recipe2!$F:$F,Hazırlık!$F23)/10+SUMIFS(Recipe2!$I:$I,Recipe2!$B:$B,Hazırlık!K$5,Recipe2!$F:$F,Hazırlık!$F23) -> 1 | L23: =SUM(G23:K23) -> 8.5 | O23: CHNB100RCB | P23: =SUM(H23:K23) -> 8.5 | Q23: =SUM(I23:K23) -> 7 | R23: =SUM(J23:K23) -> 6 | S23: =SUM(K23) -> 1
F24: CHNAVYBRCB | G24: =SUMIFS(Recipe2!$H:$H,Recipe2!$B:$B,Hazırlık!G$5,Recipe2!$F:$F,Hazırlık!$F24)/10+SUMIFS(Recipe2!$I:$I,Recipe2!$B:$B,Hazırlık!G$5,Recipe2!$F:$F,Hazırlık!$F24) -> 0 | H24: =SUMIFS(Recipe2!$H:$H,Recipe2!$B:$B,Hazırlık!H$5,Recipe2!$F:$F,Hazırlık!$F24)/10+SUMIFS(Recipe2!$I:$I,Recipe2!$B:$B,Hazırlık!H$5,Recipe2!$F:$F,Hazırlık!$F24) -> 3 | I24: =SUMIFS(Recipe2!$H:$H,Recipe2!$B:$B,Hazırlık!I$5,Recipe2!$F:$F,Hazırlık!$F24)/10+SUMIFS(Recipe2!$I:$I,Recipe2!$B:$B,Hazırlık!I$5,Recipe2!$F:$F,Hazırlık!$F24) -> 0.5 | J24: =SUMIFS(Recipe2!$H:$H,Recipe2!$B:$B,Hazırlık!J$5,Recipe2!$F:$F,Hazırlık!$F24)/10+SUMIFS(Recipe2!$I:$I,Recipe2!$B:$B,Hazırlık!J$5,Recipe2!$F:$F,Hazırlık!$F24) -> 10 | K24: =SUMIFS(Recipe2!$H:$H,Recipe2!$B:$B,Hazırlık!K$5,Recipe2!$F:$F,Hazırlık!$F24)/10+SUMIFS(Recipe2!$I:$I,Recipe2!$B:$B,Hazırlık!K$5,Recipe2!$F:$F,Hazırlık!$F24) -> 3 | L24: =SUM(G24:K24) -> 16.5 | O24: CHNAVYBRCB | P24: =SUM(H24:K24) -> 16.5 | Q24: =SUM(I24:K24) -> 13.5 | R24: =SUM(J24:K24) -> 13 | S24: =SUM(K24) -> 3
F25: CHMODENAVY | G25: =SUMIFS(Recipe2!$H:$H,Recipe2!$B:$B,Hazırlık!G$5,Recipe2!$F:$F,Hazırlık!$F25)/10+SUMIFS(Recipe2!$I:$I,Recipe2!$B:$B,Hazırlık!G$5,Recipe2!$F:$F,Hazırlık!$F25) -> 0 | H25: =SUMIFS(Recipe2!$H:$H,Recipe2!$B:$B,Hazırlık!H$5,Recipe2!$F:$F,Hazırlık!$F25)/10+SUMIFS(Recipe2!$I:$I,Recipe2!$B:$B,Hazırlık!H$5,Recipe2!$F:$F,Hazırlık!$F25) -> 0 | I25: =SUMIFS(Recipe2!$H:$H,Recipe2!$B:$B,Hazırlık!I$5,Recipe2!$F:$F,Hazırlık!$F25)/10+SUMIFS(Recipe2!$I:$I,Recipe2!$B:$B,Hazırlık!I$5,Recipe2!$F:$F,Hazırlık!$F25) -> 0 | J25: =SUMIFS(Recipe2!$H:$H,Recipe2!$B:$B,Hazırlık!J$5,Recipe2!$F:$F,Hazırlık!$F25)/10+SUMIFS(Recipe2!$I:$I,Recipe2!$B:$B,Hazırlık!J$5,Recipe2!$F:$F,Hazırlık!$F25) -> 0 | K25: =SUMIFS(Recipe2!$H:$H,Recipe2!$B:$B,Hazırlık!K$5,Recipe2!$F:$F,Hazırlık!$F25)/10+SUMIFS(Recipe2!$I:$I,Recipe2!$B:$B,Hazırlık!K$5,Recipe2!$F:$F,Hazırlık!$F25) -> 0 | L25: =SUM(G25:K25) -> 0 | O25: CHMODENAVY | P25: =SUM(H25:K25) -> 0 | Q25: =SUM(I25:K25) -> 0 | R25: =SUM(J25:K25) -> 0 | S25: =SUM(K25) -> 0
F26: MUARCB | G26: =SUMIFS(Recipe2!$H:$H,Recipe2!$B:$B,Hazırlık!G$5,Recipe2!$F:$F,Hazırlık!$F26)/10+SUMIFS(Recipe2!$I:$I,Recipe2!$B:$B,Hazırlık!G$5,Recipe2!$F:$F,Hazırlık!$F26) -> 0 | H26: =SUMIFS(Recipe2!$H:$H,Recipe2!$B:$B,Hazırlık!H$5,Recipe2!$F:$F,Hazırlık!$F26)/10+SUMIFS(Recipe2!$I:$I,Recipe2!$B:$B,Hazırlık!H$5,Recipe2!$F:$F,Hazırlık!$F26) -> 2 | I26: =SUMIFS(Recipe2!$H:$H,Recipe2!$B:$B,Hazırlık!I$5,Recipe2!$F:$F,Hazırlık!$F26)/10+SUMIFS(Recipe2!$I:$I,Recipe2!$B:$B,Hazırlık!I$5,Recipe2!$F:$F,Hazırlık!$F26) -> 1.5 | J26: =SUMIFS(Recipe2!$H:$H,Recipe2!$B:$B,Hazırlık!J$5,Recipe2!$F:$F,Hazırlık!$F26)/10+SUMIFS(Recipe2!$I:$I,Recipe2!$B:$B,Hazırlık!J$5,Recipe2!$F:$F,Hazırlık!$F26) -> 14 | K26: =SUMIFS(Recipe2!$H:$H,Recipe2!$B:$B,Hazırlık!K$5,Recipe2!$F:$F,Hazırlık!$F26)/10+SUMIFS(Recipe2!$I:$I,Recipe2!$B:$B,Hazırlık!K$5,Recipe2!$F:$F,Hazırlık!$F26) -> 3 | L26: =SUM(G26:K26) -> 20.5 | O26: MUARCB | P26: =SUM(H26:K26) -> 20.5 | Q26: =SUM(I26:K26) -> 18.5 | R26: =SUM(J26:K26) -> 17 | S26: =SUM(K26) -> 3
F27: MUABLU | G27: =SUMIFS(Recipe2!$H:$H,Recipe2!$B:$B,Hazırlık!G$5,Recipe2!$F:$F,Hazırlık!$F27)/10+SUMIFS(Recipe2!$I:$I,Recipe2!$B:$B,Hazırlık!G$5,Recipe2!$F:$F,Hazırlık!$F27) -> 0 | H27: =SUMIFS(Recipe2!$H:$H,Recipe2!$B:$B,Hazırlık!H$5,Recipe2!$F:$F,Hazırlık!$F27)/10+SUMIFS(Recipe2!$I:$I,Recipe2!$B:$B,Hazırlık!H$5,Recipe2!$F:$F,Hazırlık!$F27) -> 0.2 | I27: =SUMIFS(Recipe2!$H:$H,Recipe2!$B:$B,Hazırlık!I$5,Recipe2!$F:$F,Hazırlık!$F27)/10+SUMIFS(Recipe2!$I:$I,Recipe2!$B:$B,Hazırlık!I$5,Recipe2!$F:$F,Hazırlık!$F27) -> 0 | J27: =SUMIFS(Recipe2!$H:$H,Recipe2!$B:$B,Hazırlık!J$5,Recipe2!$F:$F,Hazırlık!$F27)/10+SUMIFS(Recipe2!$I:$I,Recipe2!$B:$B,Hazırlık!J$5,Recipe2!$F:$F,Hazırlık!$F27) -> 0 | K27: =SUMIFS(Recipe2!$H:$H,Recipe2!$B:$B,Hazırlık!K$5,Recipe2!$F:$F,Hazırlık!$F27)/10+SUMIFS(Recipe2!$I:$I,Recipe2!$B:$B,Hazırlık!K$5,Recipe2!$F:$F,Hazırlık!$F27) -> 0 | L27: =SUM(G27:K27) -> 0.2 | O27: MUABLU | P27: =SUM(H27:K27) -> 0.2 | Q27: =SUM(I27:K27) -> 0 | R27: =SUM(J27:K27) -> 0 | S27: =SUM(K27) -> 0
F28: MLEDSLIMS | G28: =SUMIFS(Recipe2!$H:$H,Recipe2!$B:$B,Hazırlık!G$5,Recipe2!$F:$F,Hazırlık!$F28)/10+SUMIFS(Recipe2!$I:$I,Recipe2!$B:$B,Hazırlık!G$5,Recipe2!$F:$F,Hazırlık!$F28) -> 0 | H28: =SUMIFS(Recipe2!$H:$H,Recipe2!$B:$B,Hazırlık!H$5,Recipe2!$F:$F,Hazırlık!$F28)/10+SUMIFS(Recipe2!$I:$I,Recipe2!$B:$B,Hazırlık!H$5,Recipe2!$F:$F,Hazırlık!$F28) -> 1 | I28: =SUMIFS(Recipe2!$H:$H,Recipe2!$B:$B,Hazırlık!I$5,Recipe2!$F:$F,Hazırlık!$F28)/10+SUMIFS(Recipe2!$I:$I,Recipe2!$B:$B,Hazırlık!I$5,Recipe2!$F:$F,Hazırlık!$F28) -> 4 | J28: =SUMIFS(Recipe2!$H:$H,Recipe2!$B:$B,Hazırlık!J$5,Recipe2!$F:$F,Hazırlık!$F28)/10+SUMIFS(Recipe2!$I:$I,Recipe2!$B:$B,Hazırlık!J$5,Recipe2!$F:$F,Hazırlık!$F28) -> 0 | K28: =SUMIFS(Recipe2!$H:$H,Recipe2!$B:$B,Hazırlık!K$5,Recipe2!$F:$F,Hazırlık!$F28)/10+SUMIFS(Recipe2!$I:$I,Recipe2!$B:$B,Hazırlık!K$5,Recipe2!$F:$F,Hazırlık!$F28) -> 0 | L28: =SUM(G28:K28) -> 5 | O28: MLEDSLIMS | P28: =SUM(H28:K28) -> 5 | Q28: =SUM(I28:K28) -> 4 | R28: =SUM(J28:K28) -> 0 | S28: =SUM(K28) -> 0
F29: LM100RCB | G29: =SUMIFS(Recipe2!$H:$H,Recipe2!$B:$B,Hazırlık!G$5,Recipe2!$F:$F,Hazırlık!$F29)/10+SUMIFS(Recipe2!$I:$I,Recipe2!$B:$B,Hazırlık!G$5,Recipe2!$F:$F,Hazırlık!$F29) -> 0 | H29: =SUMIFS(Recipe2!$H:$H,Recipe2!$B:$B,Hazırlık!H$5,Recipe2!$F:$F,Hazırlık!$F29)/10+SUMIFS(Recipe2!$I:$I,Recipe2!$B:$B,Hazırlık!H$5,Recipe2!$F:$F,Hazırlık!$F29) -> 1 | I29: =SUMIFS(Recipe2!$H:$H,Recipe2!$B:$B,Hazırlık!I$5,Recipe2!$F:$F,Hazırlık!$F29)/10+SUMIFS(Recipe2!$I:$I,Recipe2!$B:$B,Hazırlık!I$5,Recipe2!$F:$F,Hazırlık!$F29) -> 0 | J29: =SUMIFS(Recipe2!$H:$H,Recipe2!$B:$B,Hazırlık!J$5,Recipe2!$F:$F,Hazırlık!$F29)/10+SUMIFS(Recipe2!$I:$I,Recipe2!$B:$B,Hazırlık!J$5,Recipe2!$F:$F,Hazırlık!$F29) -> 10 | K29: =SUMIFS(Recipe2!$H:$H,Recipe2!$B:$B,Hazırlık!K$5,Recipe2!$F:$F,Hazırlık!$F29)/10+SUMIFS(Recipe2!$I:$I,Recipe2!$B:$B,Hazırlık!K$5,Recipe2!$F:$F,Hazırlık!$F29) -> 1 | L29: =SUM(G29:K29) -> 12 | O29: LM100RCB | P29: =SUM(H29:K29) -> 12 | Q29: =SUM(I29:K29) -> 11 | R29: =SUM(J29:K29) -> 11 | S29: =SUM(K29) -> 1
F30: LMRCB | G30: =SUMIFS(Recipe2!$H:$H,Recipe2!$B:$B,Hazırlık!G$5,Recipe2!$F:$F,Hazırlık!$F30)/10+SUMIFS(Recipe2!$I:$I,Recipe2!$B:$B,Hazırlık!G$5,Recipe2!$F:$F,Hazırlık!$F30) -> 0 | H30: =SUMIFS(Recipe2!$H:$H,Recipe2!$B:$B,Hazırlık!H$5,Recipe2!$F:$F,Hazırlık!$F30)/10+SUMIFS(Recipe2!$I:$I,Recipe2!$B:$B,Hazırlık!H$5,Recipe2!$F:$F,Hazırlık!$F30) -> 0 | I30: =SUMIFS(Recipe2!$H:$H,Recipe2!$B:$B,Hazırlık!I$5,Recipe2!$F:$F,Hazırlık!$F30)/10+SUMIFS(Recipe2!$I:$I,Recipe2!$B:$B,Hazırlık!I$5,Recipe2!$F:$F,Hazırlık!$F30) -> 0 | J30: =SUMIFS(Recipe2!$H:$H,Recipe2!$B:$B,Hazırlık!J$5,Recipe2!$F:$F,Hazırlık!$F30)/10+SUMIFS(Recipe2!$I:$I,Recipe2!$B:$B,Hazırlık!J$5,Recipe2!$F:$F,Hazırlık!$F30) -> 12 | K30: =SUMIFS(Recipe2!$H:$H,Recipe2!$B:$B,Hazırlık!K$5,Recipe2!$F:$F,Hazırlık!$F30)/10+SUMIFS(Recipe2!$I:$I,Recipe2!$B:$B,Hazırlık!K$5,Recipe2!$F:$F,Hazırlık!$F30) -> 0 | L30: =SUM(G30:K30) -> 12 | O30: LMRCB | P30: =SUM(H30:K30) -> 12 | Q30: =SUM(I30:K30) -> 12 | R30: =SUM(J30:K30) -> 12 | S30: =SUM(K30) -> 0
F31: MLROLL50 | G31: =SUMIFS(Recipe2!$H:$H,Recipe2!$B:$B,Hazırlık!G$5,Recipe2!$F:$F,Hazırlık!$F31)/10+SUMIFS(Recipe2!$I:$I,Recipe2!$B:$B,Hazırlık!G$5,Recipe2!$F:$F,Hazırlık!$F31) -> 0 | H31: =SUMIFS(Recipe2!$H:$H,Recipe2!$B:$B,Hazırlık!H$5,Recipe2!$F:$F,Hazırlık!$F31)/10+SUMIFS(Recipe2!$I:$I,Recipe2!$B:$B,Hazırlık!H$5,Recipe2!$F:$F,Hazırlık!$F31) -> 0 | I31: =SUMIFS(Recipe2!$H:$H,Recipe2!$B:$B,Hazırlık!I$5,Recipe2!$F:$F,Hazırlık!$F31)/10+SUMIFS(Recipe2!$I:$I,Recipe2!$B:$B,Hazırlık!I$5,Recipe2!$F:$F,Hazırlık!$F31) -> 0 | J31: =SUMIFS(Recipe2!$H:$H,Recipe2!$B:$B,Hazırlık!J$5,Recipe2!$F:$F,Hazırlık!$F31)/10+SUMIFS(Recipe2!$I:$I,Recipe2!$B:$B,Hazırlık!J$5,Recipe2!$F:$F,Hazırlık!$F31) -> 0.5 | K31: =SUMIFS(Recipe2!$H:$H,Recipe2!$B:$B,Hazırlık!K$5,Recipe2!$F:$F,Hazırlık!$F31)/10+SUMIFS(Recipe2!$I:$I,Recipe2!$B:$B,Hazırlık!K$5,Recipe2!$F:$F,Hazırlık!$F31) -> 0.9 | L31: =SUM(G31:K31) -> 1.4 | O31: MLROLL50 | P31: =SUM(H31:K31) -> 1.4 | Q31: =SUM(I31:K31) -> 1.4 | R31: =SUM(J31:K31) -> 1.4 | S31: =SUM(K31) -> 0.9
F32: toplam | G32: =SUM(G6:G31) -> 4 | H32: =SUM(H6:H31) -> 68.2 | I32: =SUM(I6:I31) -> 81.8 | J32: =SUM(J6:J31) -> 524.6 | K32: =SUM(K6:K31) -> 154.4 | L32: =SUM(L6:L31) -> 833 | O32: toplam | P32: =SUM(P6:P31) -> 829 | Q32: =SUM(Q6:Q31) -> 760.8 | R32: =SUM(R6:R31) -> 679 | S32: =SUM(S6:S31) -> 154.4
E35: İstasyon2
F37: =SUM(G65:K65) -> 653.3
G38: TERR030707-Sille | H38: TERR030705-Meram | I38: TERR030727-Sancak | J38: TERR030714-Adliye | K38: TERR030713-Büsan | L38: Toplam Çekilecek Stok
F39: MLR100 | G39: =SUMIFS(Recipe2!$H:$H,Recipe2!$B:$B,G$38,Recipe2!$F:$F,Hazırlık!$F39)/10+SUMIFS(Recipe2!$I:$I,Recipe2!$B:$B,G$38,Recipe2!$F:$F,Hazırlık!$F39) -> 1 | H39: =SUMIFS(Recipe2!$H:$H,Recipe2!$B:$B,H$38,Recipe2!$F:$F,Hazırlık!$F39)/10+SUMIFS(Recipe2!$I:$I,Recipe2!$B:$B,H$38,Recipe2!$F:$F,Hazırlık!$F39) -> 3 | I39: =SUMIFS(Recipe2!$H:$H,Recipe2!$B:$B,I$38,Recipe2!$F:$F,Hazırlık!$F39)/10+SUMIFS(Recipe2!$I:$I,Recipe2!$B:$B,I$38,Recipe2!$F:$F,Hazırlık!$F39) -> 1 | J39: =SUMIFS(Recipe2!$H:$H,Recipe2!$B:$B,J$38,Recipe2!$F:$F,Hazırlık!$F39)/10+SUMIFS(Recipe2!$I:$I,Recipe2!$B:$B,J$38,Recipe2!$F:$F,Hazırlık!$F39) -> 0 | K39: =SUMIFS(Recipe2!$H:$H,Recipe2!$B:$B,K$38,Recipe2!$F:$F,Hazırlık!$F39)/10+SUMIFS(Recipe2!$I:$I,Recipe2!$B:$B,K$38,Recipe2!$F:$F,Hazırlık!$F39) -> 2.5 | L39: =SUM(G39:K39) -> 7.5
F40: MFTB | G40: =SUMIFS(Recipe2!$H:$H,Recipe2!$B:$B,G$38,Recipe2!$F:$F,Hazırlık!$F40)/10+SUMIFS(Recipe2!$I:$I,Recipe2!$B:$B,G$38,Recipe2!$F:$F,Hazırlık!$F40) -> 5 | H40: =SUMIFS(Recipe2!$H:$H,Recipe2!$B:$B,H$38,Recipe2!$F:$F,Hazırlık!$F40)/10+SUMIFS(Recipe2!$I:$I,Recipe2!$B:$B,H$38,Recipe2!$F:$F,Hazırlık!$F40) -> 4 | I40: =SUMIFS(Recipe2!$H:$H,Recipe2!$B:$B,I$38,Recipe2!$F:$F,Hazırlık!$F40)/10+SUMIFS(Recipe2!$I:$I,Recipe2!$B:$B,I$38,Recipe2!$F:$F,Hazırlık!$F40) -> 4.5 | J40: =SUMIFS(Recipe2!$H:$H,Recipe2!$B:$B,J$38,Recipe2!$F:$F,Hazırlık!$F40)/10+SUMIFS(Recipe2!$I:$I,Recipe2!$B:$B,J$38,Recipe2!$F:$F,Hazırlık!$F40) -> 0 | K40: =SUMIFS(Recipe2!$H:$H,Recipe2!$B:$B,K$38,Recipe2!$F:$F,Hazırlık!$F40)/10+SUMIFS(Recipe2!$I:$I,Recipe2!$B:$B,K$38,Recipe2!$F:$F,Hazırlık!$F40) -> 5.5 | L40: =SUM(G40:K40) -> 19
F41: MLFTB | G41: =SUMIFS(Recipe2!$H:$H,Recipe2!$B:$B,G$38,Recipe2!$F:$F,Hazırlık!$F41)/10+SUMIFS(Recipe2!$I:$I,Recipe2!$B:$B,G$38,Recipe2!$F:$F,Hazırlık!$F41) -> 3 | H41: =SUMIFS(Recipe2!$H:$H,Recipe2!$B:$B,H$38,Recipe2!$F:$F,Hazırlık!$F41)/10+SUMIFS(Recipe2!$I:$I,Recipe2!$B:$B,H$38,Recipe2!$F:$F,Hazırlık!$F41) -> 0 | I41: =SUMIFS(Recipe2!$H:$H,Recipe2!$B:$B,I$38,Recipe2!$F:$F,Hazırlık!$F41)/10+SUMIFS(Recipe2!$I:$I,Recipe2!$B:$B,I$38,Recipe2!$F:$F,Hazırlık!$F41) -> 3 | J41: =SUMIFS(Recipe2!$H:$H,Recipe2!$B:$B,J$38,Recipe2!$F:$F,Hazırlık!$F41)/10+SUMIFS(Recipe2!$I:$I,Recipe2!$B:$B,J$38,Recipe2!$F:$F,Hazırlık!$F41) -> 0 | K41: =SUMIFS(Recipe2!$H:$H,Recipe2!$B:$B,K$38,Recipe2!$F:$F,Hazırlık!$F41)/10+SUMIFS(Recipe2!$I:$I,Recipe2!$B:$B,K$38,Recipe2!$F:$F,Hazırlık!$F41) -> 1 | L41: =SUM(G41:K41) -> 7
F42: MLTBLUE | G42: =SUMIFS(Recipe2!$H:$H,Recipe2!$B:$B,G$38,Recipe2!$F:$F,Hazırlık!$F42)/10+SUMIFS(Recipe2!$I:$I,Recipe2!$B:$B,G$38,Recipe2!$F:$F,Hazırlık!$F42) -> 43 | H42: =SUMIFS(Recipe2!$H:$H,Recipe2!$B:$B,H$38,Recipe2!$F:$F,Hazırlık!$F42)/10+SUMIFS(Recipe2!$I:$I,Recipe2!$B:$B,H$38,Recipe2!$F:$F,Hazırlık!$F42) -> 19 | I42: =SUMIFS(Recipe2!$H:$H,Recipe2!$B:$B,I$38,Recipe2!$F:$F,Hazırlık!$F42)/10+SUMIFS(Recipe2!$I:$I,Recipe2!$B:$B,I$38,Recipe2!$F:$F,Hazırlık!$F42) -> 19 | J42: =SUMIFS(Recipe2!$H:$H,Recipe2!$B:$B,J$38,Recipe2!$F:$F,Hazırlık!$F42)/10+SUMIFS(Recipe2!$I:$I,Recipe2!$B:$B,J$38,Recipe2!$F:$F,Hazırlık!$F42) -> 11 | K42: =SUMIFS(Recipe2!$H:$H,Recipe2!$B:$B,K$38,Recipe2!$F:$F,Hazırlık!$F42)/10+SUMIFS(Recipe2!$I:$I,Recipe2!$B:$B,K$38,Recipe2!$F:$F,Hazırlık!$F42) -> 24 | L42: =SUM(G42:K42) -> 116
F43: MLTGRAY | G43: =SUMIFS(Recipe2!$H:$H,Recipe2!$B:$B,G$38,Recipe2!$F:$F,Hazırlık!$F43)/10+SUMIFS(Recipe2!$I:$I,Recipe2!$B:$B,G$38,Recipe2!$F:$F,Hazırlık!$F43) -> 2.2 | H43: =SUMIFS(Recipe2!$H:$H,Recipe2!$B:$B,H$38,Recipe2!$F:$F,Hazırlık!$F43)/10+SUMIFS(Recipe2!$I:$I,Recipe2!$B:$B,H$38,Recipe2!$F:$F,Hazırlık!$F43) -> 1 | I43: =SUMIFS(Recipe2!$H:$H,Recipe2!$B:$B,I$38,Recipe2!$F:$F,Hazırlık!$F43)/10+SUMIFS(Recipe2!$I:$I,Recipe2!$B:$B,I$38,Recipe2!$F:$F,Hazırlık!$F43) -> 2.4 | J43: =SUMIFS(Recipe2!$H:$H,Recipe2!$B:$B,J$38,Recipe2!$F:$F,Hazırlık!$F43)/10+SUMIFS(Recipe2!$I:$I,Recipe2!$B:$B,J$38,Recipe2!$F:$F,Hazırlık!$F43) -> 1 | K43: =SUMIFS(Recipe2!$H:$H,Recipe2!$B:$B,K$38,Recipe2!$F:$F,Hazırlık!$F43)/10+SUMIFS(Recipe2!$I:$I,Recipe2!$B:$B,K$38,Recipe2!$F:$F,Hazırlık!$F43) -> 3.6 | L43: =SUM(G43:K43) -> 10.2
F44: MLTONE | G44: =SUMIFS(Recipe2!$H:$H,Recipe2!$B:$B,G$38,Recipe2!$F:$F,Hazırlık!$F44)/10+SUMIFS(Recipe2!$I:$I,Recipe2!$B:$B,G$38,Recipe2!$F:$F,Hazırlık!$F44) -> 0 | H44: =SUMIFS(Recipe2!$H:$H,Recipe2!$B:$B,H$38,Recipe2!$F:$F,Hazırlık!$F44)/10+SUMIFS(Recipe2!$I:$I,Recipe2!$B:$B,H$38,Recipe2!$F:$F,Hazırlık!$F44) -> 1 | I44: =SUMIFS(Recipe2!$H:$H,Recipe2!$B:$B,I$38,Recipe2!$F:$F,Hazırlık!$F44)/10+SUMIFS(Recipe2!$I:$I,Recipe2!$B:$B,I$38,Recipe2!$F:$F,Hazırlık!$F44) -> 3 | J44: =SUMIFS(Recipe2!$H:$H,Recipe2!$B:$B,J$38,Recipe2!$F:$F,Hazırlık!$F44)/10+SUMIFS(Recipe2!$I:$I,Recipe2!$B:$B,J$38,Recipe2!$F:$F,Hazırlık!$F44) -> 1 | K44: =SUMIFS(Recipe2!$H:$H,Recipe2!$B:$B,K$38,Recipe2!$F:$F,Hazırlık!$F44)/10+SUMIFS(Recipe2!$I:$I,Recipe2!$B:$B,K$38,Recipe2!$F:$F,Hazırlık!$F44) -> 2 | L44: =SUM(G44:K44) -> 7
F45: MLEDGE | G45: =SUMIFS(Recipe2!$H:$H,Recipe2!$B:$B,G$38,Recipe2!$F:$F,Hazırlık!$F45)/10+SUMIFS(Recipe2!$I:$I,Recipe2!$B:$B,G$38,Recipe2!$F:$F,Hazırlık!$F45) -> 50 | H45: =SUMIFS(Recipe2!$H:$H,Recipe2!$B:$B,H$38,Recipe2!$F:$F,Hazırlık!$F45)/10+SUMIFS(Recipe2!$I:$I,Recipe2!$B:$B,H$38,Recipe2!$F:$F,Hazırlık!$F45) -> 13 | I45: =SUMIFS(Recipe2!$H:$H,Recipe2!$B:$B,I$38,Recipe2!$F:$F,Hazırlık!$F45)/10+SUMIFS(Recipe2!$I:$I,Recipe2!$B:$B,I$38,Recipe2!$F:$F,Hazırlık!$F45) -> 11 | J45: =SUMIFS(Recipe2!$H:$H,Recipe2!$B:$B,J$38,Recipe2!$F:$F,Hazırlık!$F45)/10+SUMIFS(Recipe2!$I:$I,Recipe2!$B:$B,J$38,Recipe2!$F:$F,Hazırlık!$F45) -> 21 | K45: =SUMIFS(Recipe2!$H:$H,Recipe2!$B:$B,K$38,Recipe2!$F:$F,Hazırlık!$F45)/10+SUMIFS(Recipe2!$I:$I,Recipe2!$B:$B,K$38,Recipe2!$F:$F,Hazırlık!$F45) -> 41 | L45: =SUM(G45:K45) -> 136
...

Sheet Sipariş Yazdır
C2: Rut Sırası | D2: Krt | E2: Pkt
C3: 36
C4: =+Recipe2!E20 -> KÖŞEM BAKKAL - HASAN YILMAZ | D4: 36
C5: D3J232856
C6: =+Recipe2!B20 -> TERR030709-Şeker-Tekke
C7: MLR Touch Blue | D7: 2
C8: PL Night KS RCB | D8: 2
C19: Toplam | D19: =SUM(D7:D18) -> 4 | E19: =SUM(E7:E18) -> 0
C23: Rut Sırası | D23: Krt | E23: Pkt | I23: Rut Sırası | J23: Krt | K23: Pkt
C24: 24 | I24: 24
C25: NUR BAKKAL-BAHRİ DEMİR | D25: 1 | I25: NUR BAKKAL-BAHRİ DEMİR | J25: 2. sipariş
C26: D3J005897 | I26: D3J005897
C27: TERR030707-Sille | I27: TERR030707-Sille
C28: PL Midnight Blue RCB | D28: 2 | E28: 0 | I28: PL Midnight Blue RCB | J28: 2 | K28: 0
C29: MLR Touch KS Box | D29: 2 | E29: 0 | I29: MLR Touch KS Box | J29: 2 | K29: 0
C30: MLR Edge KS RCB | D30: 8 | E30: 0 | I30: MLR Edge KS RCB | J30: 8 | K30: 0
C31: MLR Touch Blue | D31: 10 | E31: 0 | I31: MLR Touch Blue | J31: 15 | K31: 0
C32: CH NavyB 100 RCB | D32: 1 | E32: 0 | I32: CH NavyB 100 RCB | J32: 1 | K32: 0
C33: PL Night 100 | D33: 8 | E33: 0 | I33: PL Night 100 | J33: 8 | K33: 0
C34: MLR KS Box | D34: 2 | E34: 0 | I34: MLR KS Box | J34: 2 | K34: 0
C35: CH NAVY BLUE RCB | D35: 1 | E35: 0 | I35: CH NAVY BLUE RCB | J35: 1 | K35: 0
C36: PL Night KS RCB | D36: 15 | E36: 0 | I36: PL Night KS RCB | J36: 20 | K36: 0
C37: MUA Rosso KS RCB | D37: 2 | E37: 0 | I37: MUA Rosso KS RCB | J37: 2 | K37: 5
C38: MLR Edge Blue KS RCB | D38: 1 | E38: 0 | I38: MLR Edge Blue KS RCB | J38: 1 | K38: 0
C40: Toplam | D40: =SUM(D28:D39) -> 52 | E40: =SUM(E28:E39) -> 0 | I40: Toplam | J40: =SUM(J28:J39) -> 62 | K40: =SUM(K28:K39) -> 5

Sheet Recip1
A1: Pozisyon | B1: Territory | C1: SiparişKodu | D1: BayiKodu | E1: BayiAdı | F1: ÜrünKodu | G1: ÜrünAdı | H1: Paket | I1: Karton | J1: ÖdemeTipi | K1: SiparişTarihi | L1: TeslimatTarihi | M1: BayiRutSırası
A2: D3JDR07 | B2: TERR030707-Sille | C2: D3J005897253121 | D2: D3J005897 | E2: NUR BAKKAL-BAHRİ DEMİR | F2: PLMNRCB | G2: PL Midnight Blue RCB | H2: 0 | I2: 2 | J2: VADE | K2: 06.11.2025 08:35:00 | L2: 07.11.2025 00:00:00 | M2: 24
A3: D3JDR07 | B3: TERR030707-Sille | C3: D3J005897253121 | D3: D3J005897 | E3: NUR BAKKAL-BAHRİ DEMİR | F3: MLFTB | G3: MLR Touch KS Box | H3: 0 | I3: 2 | J3: VADE | K3: 06.11.2025 08:35:00 | L3: 07.11.2025 00:00:00 | M3: 24
A4: D3JDR07 | B4: TERR030707-Sille | C4: D3J005897253121 | D4: D3J005897 | E4: NUR BAKKAL-BAHRİ DEMİR | F4: MLEDGE | G4: MLR Edge KS RCB | H4: 0 | I4: 8 | J4: VADE | K4: 06.11.2025 08:35:00 | L4: 07.11.2025 00:00:00 | M4: 24
A5: D3JDR07 | B5: TERR030707-Sille | C5: D3J005897253121 | D5: D3J005897 | E5: NUR BAKKAL-BAHRİ DEMİR | F5: MLTBLUE | G5: MLR Touch Blue | H5: 0 | I5: 10 | J5: VADE | K5: 06.11.2025 08:35:00 | L5: 07.11.2025 00:00:00 | M5: 24
A6: D3JDR07 | B6: TERR030707-Sille | C6: D3J005897253121 | D6: D3J005897 | E6: NUR BAKKAL-BAHRİ DEMİR | F6: CHNB100RCB | G6: CH NavyB 100 RCB | H6: 0 | I6: 1 | J6: VADE | K6: 06.11.2025 08:35:00 | L6: 07.11.2025 00:00:00 | M6: 24
A7: D3JDR07 | B7: TERR030707-Sille | C7: D3J005897253121 | D7: D3J005897 | E7: NUR BAKKAL-BAHRİ DEMİR | F7: PL100 | G7: PL Night 100 | H7: 0 | I7: 8 | J7: VADE | K7: 06.11.2025 08:35:00 | L7: 07.11.2025 00:00:00 | M7: 24
A8: D3JDR07 | B8: TERR030707-Sille | C8: D3J005897253121 | D8: D3J005897 | E8: NUR BAKKAL-BAHRİ DEMİR | F8: MFTB | G8: MLR KS Box | H8: 0 | I8: 2 | J8: VADE | K8: 06.11.2025 08:35:00 | L8: 07.11.2025 00:00:00 | M8: 24
A9: D3JDR07 | B9: TERR030707-Sille | C9: D3J005897253121 | D9: D3J005897 | E9: NUR BAKKAL-BAHRİ DEMİR | F9: CHNAVYBRCB | G9: CH NAVY BLUE RCB | H9: 0 | I9: 1 | J9: VADE | K9: 06.11.2025 08:35:00 | L9: 07.11.2025 00:00:00 | M9: 24
A10: D3JDR07 | B10: TERR030707-Sille | C10: D3J005897253121 | D10: D3J005897 | E10: NUR BAKKAL-BAHRİ DEMİR | F10: PLRC | G10: PL Night KS RCB | H10: 0 | I10: 15 | J10: VADE | K10: 06.11.2025 08:35:00 | L10: 07.11.2025 00:00:00 | M10: 24
A11: D3JDR07 | B11: TERR030707-Sille | C11: D3J005897253121 | D11: D3J005897 | E11: NUR BAKKAL-BAHRİ DEMİR | F11: MUARCB | G11: MUA Rosso KS RCB | H11: 0 | I11: 2 | J11: VADE | K11: 06.11.2025 08:35:00 | L11: 07.11.2025 00:00:00 | M11: 24
A12: D3JDR07 | B12: TERR030707-Sille | C12: D3J005897253121 | D12: D3J005897 | E12: NUR BAKKAL-BAHRİ DEMİR | F12: MLEDBLUE | G12: MLR Edge Blue KS RCB | H12: 0 | I12: 1 | J12: VADE | K12: 06.11.2025 08:35:00 | L12: 07.11.2025 00:00:00 | M12: 24
A13: D3JDR07 | B13: TERR030707-Sille | C13: D3J001563253121 | D13: D3J001563 | E13: ARPİN NAK. GIDA MAD. KUN.İMALT.SAN. TİC. LTD.ŞTİ. | F13: PLMNRCB | G13: PL Midnight Blue RCB | H13: 0 | I13: 2 | J13: CASH | K13: 06.11.2025 09:02:00 | L13: 07.11.2025 00:00:00 | M13: 25
... A222: D3JDR08 | B222: TERR030708-Form | C222: D3J232439253121 | D222: D3J232439 | E222: PAŞALI MARKET MANAV-MURAT TARAKCI | F222: MLEDBLUE | G222: MLR Edge Blue KS RCB | H222: 0 | I222: 1 | J222: HAVALE | K222: 06.11.2025 13:58:00 | L222: 07.11.2025 00:00:00 | M222: 35
